>>> %Run madeirao.py
start
cine Super K o Ãºltimo cinema de rua de Boa Vista
1
2024-07-24 03:06:23.084591
********************************
Traceback (most recent call last):
  File "/home/pi/madeirao.py", line 30, in <module>
    driver.get("https://www.google.com.br/")
  File "/usr/local/lib/python3.7/dist-packages/selenium/webdriver/remote/webdriver.py", line 333, in get
    self.execute(Command.GET, {'url': url})
  File "/usr/local/lib/python3.7/dist-packages/selenium/webdriver/remote/webdriver.py", line 321, in execute
    self.error_handler.check_response(response)
  File "/usr/local/lib/python3.7/dist-packages/selenium/webdriver/remote/errorhandler.py", line 242, in check_response
    raise exception_class(message, screen, stacktrace)
selenium.common.exceptions.InvalidSessionIdException: Message: invalid session id


During handling of the above exception, another exception occurred:

Traceback (most recent call last):
  File "/home/pi/madeirao.py", line 118, in <module>
    driver.close()
  File "/usr/local/lib/python3.7/dist-packages/selenium/webdriver/remote/webdriver.py", line 688, in close
    self.execute(Command.CLOSE)
  File "/usr/local/lib/python3.7/dist-packages/selenium/webdriver/remote/webdriver.py", line 321, in execute
    self.error_handler.check_response(response)
  File "/usr/local/lib/python3.7/dist-packages/selenium/webdriver/remote/errorhandler.py", line 242, in check_response
    raise exception_class(message, screen, stacktrace)
selenium.common.exceptions.InvalidSessionIdException: Message: invalid session id

>>> 
